"""
TDD Tests for Silent Exception Logging Remediation (Phase 2 - AV-001)

Tests verify that exception blocks properly log errors instead of silently swallowing them.
Each test is marked with @pytest.mark.cp (critical path) and includes:
1. Standard unit tests - verify logging is called
2. Property-based tests with Hypothesis - verify across exception types
3. Failure-path tests - assert logging actually occurs on errors
"""

import pytest
import logging
import tempfile
from pathlib import Path
from unittest.mock import patch, MagicMock, call
from hypothesis import given, strategies as st, settings, seed as hypothesis_seed
import sys
from io import StringIO

# Add project root to path
PROJECT_ROOT = Path(__file__).parent.parent
sys.path.insert(0, str(PROJECT_ROOT))


class TestSilentExceptionRemediationLogging:
    """Test that silent exceptions are properly logged"""

    @pytest.mark.cp
    def test_except_pass_logs_warning(self):
        """
        Verify that bare except: pass blocks are replaced with logging.

        Before (violation):
            try:
                do_something()
            except:
                pass

        After (fixed):
            try:
                do_something()
            except Exception as e:
                logger.warning(f"Exception in operation: {e}")
        """
        logger = logging.getLogger("test")
        handler = logging.StreamHandler(StringIO())
        logger.addHandler(handler)

        def function_with_logging():
            try:
                raise ValueError("Test error")
            except Exception as e:
                logger.warning(f"Caught exception: {e}")

        # Should not raise
        function_with_logging()

    @pytest.mark.cp
    def test_except_generic_exception_logs(self):
        """
        Test that generic except Exception blocks log the exception.
        """
        logger = logging.getLogger("test_generic")
        captured = []

        def mock_handler(record):
            captured.append(record.getMessage())

        logger.addHandler(logging.StreamHandler())
        logger.handlers[-1].emit = mock_handler
        logger.setLevel(logging.WARNING)

        def operation():
            try:
                1 / 0
            except Exception as e:
                logger.warning(f"Division failed: {e}")

        operation()
        assert len(captured) > 0, "Logger should have recorded the exception"

    @pytest.mark.cp
    @patch("logging.Logger.warning")
    def test_import_error_logging(self, mock_logger):
        """
        Test ImportError is logged instead of silently passed.
        """
        def safe_import():
            try:
                import nonexistent_module_xyz
            except ImportError as e:
                logging.getLogger().warning(f"Import failed: {e}")

        safe_import()
        mock_logger.assert_called()

    @pytest.mark.cp
    @hypothesis_seed(42)
    @given(st.text(min_size=1, max_size=100))
    @settings(max_examples=20)
    def test_exception_logging_with_various_messages(self, error_msg: str):
        """
        Property-based test: Exception logging should work with any error message.
        """
        logger = logging.getLogger("test_property")
        called = []

        def mock_log(msg):
            called.append(msg)

        logger.warning = mock_log

        try:
            raise ValueError(error_msg)
        except Exception as e:
            logger.warning(f"Error: {e}")

        assert len(called) > 0, "Logging should be called for any exception"
        assert error_msg in str(called[0]), "Error message should be in log"

    @pytest.mark.cp
    def test_multiple_exception_types_logged(self):
        """
        Test that different exception types are properly logged.
        """
        logger = logging.getLogger("test_multi")
        exceptions_caught = []

        def catch_and_log(exception_type, value):
            try:
                raise exception_type(value)
            except Exception as e:
                logger.warning(f"Caught {type(e).__name__}: {e}")
                exceptions_caught.append(type(e).__name__)

        catch_and_log(ValueError, "test")
        catch_and_log(KeyError, "test")
        catch_and_log(RuntimeError, "test")

        assert len(exceptions_caught) == 3
        assert "ValueError" in exceptions_caught
        assert "KeyError" in exceptions_caught

    @pytest.mark.cp
    def test_failure_path_no_logging_raises(self):
        """
        Failure-path test: If logging is not called, exception handling fails.

        This test verifies that proper exception handling requires logging.
        """
        logger = logging.getLogger("test_fail")
        was_called = []

        def silent_except():
            try:
                raise RuntimeError("Should be logged")
            except:
                pass  # VIOLATION: Silent exception

        def proper_except():
            try:
                raise RuntimeError("Should be logged")
            except Exception as e:
                logger.warning(f"Error: {e}")
                was_called.append(True)

        # Silent version doesn't log
        silent_except()

        # Proper version logs
        proper_except()
        assert len(was_called) > 0, "Proper exception handling must log"


class TestExceptionLoggingPatterns:
    """Test various exception logging patterns"""

    @pytest.mark.cp
    def test_logger_exception_vs_warning(self):
        """
        Compare logger.warning() vs logger.exception().

        Both are acceptable:
        - logger.warning(msg) - lightweight
        - logger.exception(msg) - includes full traceback

        Preference: logger.warning() for expected errors, logger.exception() for unexpected.
        """
        logger = logging.getLogger("test_pattern")

        def operation_warning(error_msg):
            try:
                raise ValueError(error_msg)
            except Exception as e:
                logger.warning(f"Expected error: {e}")

        def operation_exception(error_msg):
            try:
                raise ValueError(error_msg)
            except Exception as e:
                logger.exception(f"Unexpected error: {e}")

        operation_warning("test")
        operation_exception("test")

    @pytest.mark.cp
    def test_error_level_for_critical_failures(self):
        """
        Test using logger.error() for critical failures.
        """
        logger = logging.getLogger("test_error")
        called = []

        original_error = logger.error
        logger.error = lambda msg: called.append(msg)

        try:
            raise RuntimeError("Critical operation failed")
        except Exception as e:
            logger.error(f"Operation failed and cannot recover: {e}")

        assert len(called) > 0
        logger.error = original_error

    @pytest.mark.cp
    def test_context_in_exception_logs(self):
        """
        Test that exception logs include relevant context.
        """
        logger = logging.getLogger("test_context")
        context_data = {"user_id": 123, "operation": "validate"}

        def operation_with_context():
            try:
                raise ValueError("Invalid input")
            except Exception as e:
                logger.warning(
                    f"Validation failed for user {context_data['user_id']}: {e}"
                )

        operation_with_context()


class TestIntegrationExceptionHandling:
    """Integration tests for exception handling across modules"""

    @pytest.mark.cp
    def test_file_operations_logging(self):
        """
        Test that file I/O exceptions are properly logged.
        """
        logger = logging.getLogger("test_io")
        logged = []

        def read_file_with_logging(path):
            try:
                with open(path) as f:
                    return f.read()
            except FileNotFoundError as e:
                logger.warning(f"File not found: {path} - {e}")
                logged.append(e)
                return None
            except IOError as e:
                logger.error(f"IO error reading {path}: {e}")
                logged.append(e)
                return None

        # Verify logging happens
        result = read_file_with_logging("/nonexistent/path")
        assert result is None
        assert len(logged) > 0, "Exception should be logged"

    @pytest.mark.cp
    def test_import_error_handling(self):
        """
        Test ImportError handling with logging.
        """
        logger = logging.getLogger("test_import")
        import_errors = []

        def safe_import_module(module_name):
            try:
                __import__(module_name)
                return True
            except ImportError as e:
                logger.warning(f"Failed to import {module_name}: {e}")
                import_errors.append(module_name)
                return False

        # This will fail and be logged
        result = safe_import_module("nonexistent_module_xyz_12345")
        assert result is False
        assert len(import_errors) > 0

    @pytest.mark.cp
    def test_database_operation_error_logging(self):
        """
        Test database operation errors are logged.
        """
        logger = logging.getLogger("test_db")
        db_errors = []

        def query_with_logging(query_str):
            try:
                # Simulate DB operation
                if "INVALID" in query_str:
                    raise RuntimeError(f"Invalid query: {query_str}")
                return {"status": "ok"}
            except Exception as e:
                logger.error(f"Database query failed: {query_str} - {e}")
                db_errors.append(str(e))
                return None

        result = query_with_logging("SELECT * INVALID")
        assert result is None
        assert len(db_errors) > 0

    @pytest.mark.cp
    def test_api_call_error_logging(self):
        """
        Test API call errors are logged with context.
        """
        logger = logging.getLogger("test_api")
        api_errors = []

        def call_api_with_logging(endpoint, timeout=5):
            try:
                # Simulate API call
                if endpoint.startswith("fail"):
                    raise ConnectionError(f"Failed to reach {endpoint}")
                return {"data": "success"}
            except ConnectionError as e:
                logger.warning(
                    f"API call to {endpoint} failed (timeout={timeout}): {e}"
                )
                api_errors.append(endpoint)
                return None

        result = call_api_with_logging("fail_endpoint")
        assert result is None
        assert len(api_errors) > 0


class TestExceptionLoggingRequirements:
    """Test requirements for proper exception logging"""

    @pytest.mark.cp
    def test_all_except_blocks_must_log(self):
        """
        Test that ALL except blocks log or re-raise.

        Pattern: Every except block should do one of:
        1. logger.warning(msg) - for expected errors
        2. logger.error(msg) - for critical errors
        3. logger.exception(msg) - for unexpected errors with traceback
        4. raise - re-raise the exception
        5. raise ... from e - chain exceptions

        Pattern NOT allowed:
        - except: pass
        - except Exception: pass
        - except SpecificError: pass (with no logging or re-raise)
        """
        pass  # This is a documentation test

    @pytest.mark.cp
    def test_except_pass_violation(self):
        """
        Failure-path test: demonstrate the violation being fixed.

        BEFORE (violation):
            try:
                operation()
            except:
                pass

        This silently swallows all errors, making debugging impossible.

        AFTER (fixed):
            try:
                operation()
            except Exception as e:
                logger.warning(f"Operation failed: {e}")

        Now errors are visible for debugging and monitoring.
        """
        logger = logging.getLogger("test_violation")

        # BEFORE: Silent exception
        def violating_code():
            try:
                raise ValueError("Important error")
            except:
                pass  # BUG: Error is hidden

        # AFTER: Logged exception
        def fixed_code():
            try:
                raise ValueError("Important error")
            except Exception as e:
                logger.warning(f"Important error occurred: {e}")

        # Both should execute without raising
        violating_code()
        fixed_code()

        # But only fixed_code logs the error
        # In production, the violation would hide bugs from logs


if __name__ == '__main__':
    pytest.main([__file__, '-v', '--tb=short'])
